Workbook
Name AMBER_MAX: 'Cover & Instructions'!$C$36
Name RED_MAX: 'Cover & Instructions'!$C$35
Name RISK_CRIT: 'Cover & Instructions'!$C$37
Name RISK_HIGH: 'Cover & Instructions'!$C$38
Name RISK_MED: 'Cover & Instructions'!$C$39

Sheet Cover & Instructions
B2: FAB - AWS Cloud Internet Breakout
B3: Independent Technical Assessment Workbook (SOW-aligned)
B4: Confidential - For Authorized Use Only
B6: ASSESSMENT DETAILS | E6: WORKBOOK STRUCTURE
B7: Customer Name: | C7: First Abu Dhabi Bank (FAB) | E7: Tab | F7: Name | G7: Description
B8: Engagement ID: | C8: [Enter Engagement ID] | E8: 1 | F8: Cover & Instructions | G8: Metadata, scoring guide, parameters, instructions
B9: SOW Reference: | C9: [Enter SOW No.] | E9: 2 | F9: SOW Traceability | G9: SOW clause to assessment item coverage (live)
B10: Assessment Date: | C10: [DD/MM/YYYY] | E10: 3 | F10: Architecture Review | G10: SOW 2.1 - design, VPC/CIDR, TGW, DNS, IGW/NAT, LBs, IaC
B11: Lead Assessor: | C11: [Enter Name] | E11: 4 | F11: Traffic Flow Validation | G11: SOW 2.2 - inbound/outbound/east-west, symmetry, insertion, steering
B12: Secondary Assessor(s): | C12: [Enter Name(s)] | E12: 5 | F12: Traffic Flow Matrix | G12: Per-flow path, inspection point and return-path validation
B13: Scope: | C13: AWS Cloud Internet Breakout - Architecture, Traffic Flow, Resilience, Third-Party Integration, Migration & Cutover | E13: 6 | F13: HA & Resilience | G13: SOW 2.3 - multi-AZ, failure modes, convergence, asymmetry
B14: AWS Account(s) in Scope: | C14: [Enter Account IDs] | E14: 7 | F14: UAT Failover Scenarios | G14: Failover scenarios, expected results, measured recovery
B15: AWS Region(s): | C15: [Enter Region(s)] | E15: 8 | F15: Third-Party Integration | G15: SOW 2.4 - NVAs, IPS/IDS/WAF, proxy, GENEVE, health checks
B16: Assessment Version: | C16: 1 | E16: 9 | F16: Migration & Cutover | G16: SOW 2.5 - switchover, rollback, black-hole windows, readiness
B17: Document Classification: | C17: Confidential | E17: 10 | F17: Go-NoGo Criteria | G17: Go/No-Go criteria with automatic decision
E18: 11 | F18: Integration Risk Register | G18: AWS and third-party interoperability risks and mitigations
B19: SCORING LEGEND | E19: 12 | F19: Findings & Remediation | G19: Consolidated findings, risk rating and remediation plan
B20: Score | C20: Maturity Level | D20: Description | E20: 13 | F20: Deliverables Tracker | G20: Seven SOW deliverables and partner responsibilities
B21: 1 | C21: Not Implemented | D21: Control or capability is absent; no evidence of implementation or planning. | E21: 14 | F21: Executive Dashboard | G21: Scores, RAG distribution, risks, UAT, cutover readiness
B22: 2 | C22: Initial / Ad-Hoc | D22: Partial or reactive implementation; not standardized, inconsistent.
B23: 3 | C23: Defined / Managed | D23: Documented and consistently applied; meets baseline requirements. | E23: INSTRUCTIONS FOR USE
B24: 4 | C24: Quantitatively Managed | D24: Proactive monitoring, metrics-driven; exceeds baseline. | E24: 1. Complete the Assessment Details on this tab; set thresholds in Parameters if FAB requires different bands.
B25: 5 | C25: Optimized / Automated | D25: Fully automated, continuously improved; industry-leading. | E25: 2. Review the SOW Traceability tab: every SOW clause must show 'Covered' (no GAP).
E26: 3. Work through tabs 3-9 (Architecture, Traffic Flow, HA & Resilience, Third-Party, Migration, plus the Flow Matrix and UAT tabs). Score each item 1-5 using the Scoring Legend; RAG is calculated automatically.
B27: RAG STATUS GUIDE | E27: 4. For every item record Findings and Recommendations, and attach evidence per the Evidence / Validation Method column. Leave Score blank if an item is not applicable.
B28: Status | C28: Criteria | D28: Score Range | E28: 5. Record each issue as a row in Findings & Remediation with Evidence, Impact, Likelihood, Impact score, Recommendation, Dependency and Owner (SOW Section 4 requirement).
B29: RED | C29: Critical gap - immediate remediation required. High risk. | D29: =TEXT(1,"0.0")&" - "&TEXT(RED_MAX,"0.0") -> 1.0 - 2.0 | E29: 6. Validate every row of the Traffic Flow Matrix and execute the UAT Failover Scenarios; record measured recovery times against FAB-agreed targets.
B30: AMBER | C30: Partial implementation - improvement needed in 30-60 days. | D30: =TEXT(RED_MAX+0.1,"0.0")&" - "&TEXT(AMBER_MAX,"0.0") -> 2.1 - 3.5 | E30: 7. Rate the seeded candidate risks in the Integration Risk Register (Likelihood x Impact) and add any new interoperability risks.
B31: GREEN | C31: Meets or exceeds requirements - minor improvements only. | D31: =TEXT(AMBER_MAX+0.1,"0.0")&" - "&TEXT(5,"0.0") -> 3.6 - 5.0 | E31: 8. Update the Go-NoGo Criteria status; the overall GO / NO-GO / PENDING decision is calculated automatically.
E32: 9. Track each SOW deliverable and FAB review comments on the Deliverables Tracker.
B33: PARAMETERS (edit blue cells to change thresholds workbook-wide) | E33: 10. Executive Dashboard summarises everything live - review before the FAB readout. Blue cells are inputs; grey italic text is placeholder text to overwrite.
B34: Parameter | C34: Value | D34: Notes
B35: RED if score <= | C35: 2 | D35: Scores at or below this value are RED (assessment items and domain averages). Source: reference workbook RAG guide (1.0 - 2.0).
B36: AMBER if score <= | C36: 3.5 | D36: Scores above RED and up to this value are AMBER; above it GREEN. Source: reference workbook RAG guide (2.1 - 3.5).
B37: Risk Critical if score >= | C37: 20 | D37: Likelihood x Impact (1-25). Assessor-set threshold - adjust to FAB risk appetite.
B38: Risk High if score >= | C38: 12 | D38: Assessor-set threshold - adjust to FAB risk appetite.
B39: Risk Medium if score >= | C39: 6 | D39: Below this value the risk is Low. Assessor-set threshold - adjust to FAB risk appetite.
B41: EXAMPLE FINDING ENTRY (ILLUSTRATIVE ONLY - not an assessed finding)
B42: Finding Summary | C42: Inspection VPC TGW attachment has appliance mode disabled. | D42: One line stating what is wrong and where.
B43: Evidence Reference | C43: TGW attachment attribute export; VPC Flow Logs showing one-directional flows. | D43: Screenshot/export/log reference so FAB can verify.
...

Sheet SOW Traceability
A1: SOW TRACEABILITY MATRIX
A2: Every SOW scope clause maps to assessment items; coverage is calculated live from the assessment tabs (GAP = no item mapped)
A4: SOW Ref | B4: SOW Section | C4: SOW Requirement | D4: Assessment Tab | E4: Items Mapped | F4: Items Scored | G4: Avg Score | H4: Coverage Check | I4: Linked Deliverable # | J4: Workbook Coverage
A5: 1 | B5: 1. Objective | C5: Independent technical assessment of the AWS Cloud Internet Breakout architecture before production rollout: design, routing, security controls, resilience, migration readiness and key risks. | D5: All tabs | H5: n/a | I5: All | J5: Consolidated in Executive Dashboard
A6: 2.1.1 | B6: 2.1 Architecture Review | C6: Review the design against FAB security, availability and operational requirements. | D6: Architecture Review | E6: =COUNTIF('Architecture Review'!$F$5:$F$300,$A6) -> 6 | F6: =COUNTIFS('Architecture Review'!$F$5:$F$300,$A6,'Architecture Review'!$G$5:$G$300,">0") -> 0 | G6: =IFERROR(AVERAGEIFS('Architecture Review'!$G$5:$G$300,'Architecture Review'!$F$5:$F$300,$A6),"") | H6: =IF(E6>0,"Covered","GAP") -> Covered | I6: 1 | J6: =IF(E6=0,"No item mapped",IF(F6=E6,"All items scored",F6&" of "&E6&" items scored")) -> 0 of 6 items scored
A7: 2.1.2 | B7: 2.1 Architecture Review | C7: Validate VPCs, CIDRs, subnets and Availability Zone placement. | D7: Architecture Review | E7: =COUNTIF('Architecture Review'!$F$5:$F$300,$A7) -> 6 | F7: =COUNTIFS('Architecture Review'!$F$5:$F$300,$A7,'Architecture Review'!$G$5:$G$300,">0") -> 0 | G7: =IFERROR(AVERAGEIFS('Architecture Review'!$G$5:$G$300,'Architecture Review'!$F$5:$F$300,$A7),"") | H7: =IF(E7>0,"Covered","GAP") -> Covered | I7: 1 | J7: =IF(E7=0,"No item mapped",IF(F7=E7,"All items scored",F7&" of "&E7&" items scored")) -> 0 of 6 items scored
A8: 2.1.3 | B8: 2.1 Architecture Review | C8: Assess Transit Gateway, route tables, propagation and routing controls. | D8: Architecture Review | E8: =COUNTIF('Architecture Review'!$F$5:$F$300,$A8) -> 9 | F8: =COUNTIFS('Architecture Review'!$F$5:$F$300,$A8,'Architecture Review'!$G$5:$G$300,">0") -> 0 | G8: =IFERROR(AVERAGEIFS('Architecture Review'!$G$5:$G$300,'Architecture Review'!$F$5:$F$300,$A8),"") | H8: =IF(E8>0,"Covered","GAP") -> Covered | I8: 1 | J8: =IF(E8=0,"No item mapped",IF(F8=E8,"All items scored",F8&" of "&E8&" items scored")) -> 0 of 9 items scored
A9: 2.1.4 | B9: 2.1 Architecture Review | C9: DNS architecture and name resolution. | D9: Architecture Review | E9: =COUNTIF('Architecture Review'!$F$5:$F$300,$A9) -> 5 | F9: =COUNTIFS('Architecture Review'!$F$5:$F$300,$A9,'Architecture Review'!$G$5:$G$300,">0") -> 0 | G9: =IFERROR(AVERAGEIFS('Architecture Review'!$G$5:$G$300,'Architecture Review'!$F$5:$F$300,$A9),"") | H9: =IF(E9>0,"Covered","GAP") -> Covered | I9: 1 | J9: =IF(E9=0,"No item mapped",IF(F9=E9,"All items scored",F9&" of "&E9&" items scored")) -> 0 of 5 items scored
A10: 2.1.5 | B10: 2.1 Architecture Review | C10: Internet Gateway and NAT Gateway design. | D10: Architecture Review | E10: =COUNTIF('Architecture Review'!$F$5:$F$300,$A10) -> 6 | F10: =COUNTIFS('Architecture Review'!$F$5:$F$300,$A10,'Architecture Review'!$G$5:$G$300,">0") -> 0 | G10: =IFERROR(AVERAGEIFS('Architecture Review'!$G$5:$G$300,'Architecture Review'!$F$5:$F$300,$A10),"") | H10: =IF(E10>0,"Covered","GAP") -> Covered | I10: 1 | J10: =IF(E10=0,"No item mapped",IF(F10=E10,"All items scored",F10&" of "&E10&" items scored")) -> 0 of 6 items scored
A11: 2.1.6 | B11: 2.1 Architecture Review | C11: Application Load Balancer, Network Load Balancer and Gateway Load Balancer design. | D11: Architecture Review | E11: =COUNTIF('Architecture Review'!$F$5:$F$300,$A11) -> 6 | F11: =COUNTIFS('Architecture Review'!$F$5:$F$300,$A11,'Architecture Review'!$G$5:$G$300,">0") -> 0 | G11: =IFERROR(AVERAGEIFS('Architecture Review'!$G$5:$G$300,'Architecture Review'!$F$5:$F$300,$A11),"") | H11: =IF(E11>0,"Covered","GAP") -> Covered | I11: 1 | J11: =IF(E11=0,"No item mapped",IF(F11=E11,"All items scored",F11&" of "&E11&" items scored")) -> 0 of 6 items scored
A12: 2.1.7 | B12: 2.1 Architecture Review | C12: Review Terraform or CloudFormation against the approved design. | D12: Architecture Review | E12: =COUNTIF('Architecture Review'!$F$5:$F$300,$A12) -> 5 | F12: =COUNTIFS('Architecture Review'!$F$5:$F$300,$A12,'Architecture Review'!$G$5:$G$300,">0") -> 0 | G12: =IFERROR(AVERAGEIFS('Architecture Review'!$G$5:$G$300,'Architecture Review'!$F$5:$F$300,$A12),"") | H12: =IF(E12>0,"Covered","GAP") -> Covered | I12: 1 | J12: =IF(E12=0,"No item mapped",IF(F12=E12,"All items scored",F12&" of "&E12&" items scored")) -> 0 of 5 items scored
A13: 2.2.1 | B13: 2.2 Traffic Flow Validation | C13: Review inbound, outbound and east-west traffic flows. | D13: Traffic Flow Validation | E13: =COUNTIF('Traffic Flow Validation'!$F$5:$F$300,$A13) -> 16 | F13: =COUNTIFS('Traffic Flow Validation'!$F$5:$F$300,$A13,'Traffic Flow Validation'!$G$5:$G$300,">0") -> 0 | G13: =IFERROR(AVERAGEIFS('Traffic Flow Validation'!$G$5:$G$300,'Traffic Flow Validation'!$F$5:$F$300,$A13),"") | H13: =IF(E13>0,"Covered","GAP") -> Covered | I13: 2 | J13: =IF(E13=0,"No item mapped",IF(F13=E13,"All items scored",F13&" of "&E13&" items scored")) -> 0 of 16 items scored
A14: 2.2.2 | B14: 2.2 Traffic Flow Validation | C14: Validate L3/L7 paths, inspection, proxy, firewall and load-balancing dependencies. | D14: Traffic Flow Validation | E14: =COUNTIF('Traffic Flow Validation'!$F$5:$F$300,$A14) -> 5 | F14: =COUNTIFS('Traffic Flow Validation'!$F$5:$F$300,$A14,'Traffic Flow Validation'!$G$5:$G$300,">0") -> 0 | G14: =IFERROR(AVERAGEIFS('Traffic Flow Validation'!$G$5:$G$300,'Traffic Flow Validation'!$F$5:$F$300,$A14),"") | H14: =IF(E14>0,"Covered","GAP") -> Covered | I14: 2 | J14: =IF(E14=0,"No item mapped",IF(F14=E14,"All items scored",F14&" of "&E14&" items scored")) -> 0 of 5 items scored
A15: 2.2.3 | B15: 2.2 Traffic Flow Validation | C15: Verify routing symmetry and return-path design. | D15: Traffic Flow Validation | E15: =COUNTIF('Traffic Flow Validation'!$F$5:$F$300,$A15) -> 3 | F15: =COUNTIFS('Traffic Flow Validation'!$F$5:$F$300,$A15,'Traffic Flow Validation'!$G$5:$G$300,">0") -> 0 | G15: =IFERROR(AVERAGEIFS('Traffic Flow Validation'!$G$5:$G$300,'Traffic Flow Validation'!$F$5:$F$300,$A15),"") | H15: =IF(E15>0,"Covered","GAP") -> Covered | I15: 2 | J15: =IF(E15=0,"No item mapped",IF(F15=E15,"All items scored",F15&" of "&E15&" items scored")) -> 0 of 3 items scored
A16: 2.2.4 | B16: 2.2 Traffic Flow Validation | C16: Review service insertion and inspection flows. | D16: Traffic Flow Validation | E16: =COUNTIF('Traffic Flow Validation'!$F$5:$F$300,$A16) -> 3 | F16: =COUNTIFS('Traffic Flow Validation'!$F$5:$F$300,$A16,'Traffic Flow Validation'!$G$5:$G$300,">0") -> 0 | G16: =IFERROR(AVERAGEIFS('Traffic Flow Validation'!$G$5:$G$300,'Traffic Flow Validation'!$F$5:$F$300,$A16),"") | H16: =IF(E16>0,"Covered","GAP") -> Covered | I16: 2 | J16: =IF(E16=0,"No item mapped",IF(F16=E16,"All items scored",F16&" of "&E16&" items scored")) -> 0 of 3 items scored
A17: 2.2.5 | B17: 2.2 Traffic Flow Validation | C17: Confirm security-control placement and traffic steering. | D17: Traffic Flow Validation | E17: =COUNTIF('Traffic Flow Validation'!$F$5:$F$300,$A17) -> 4 | F17: =COUNTIFS('Traffic Flow Validation'!$F$5:$F$300,$A17,'Traffic Flow Validation'!$G$5:$G$300,">0") -> 0 | G17: =IFERROR(AVERAGEIFS('Traffic Flow Validation'!$G$5:$G$300,'Traffic Flow Validation'!$F$5:$F$300,$A17),"") | H17: =IF(E17>0,"Covered","GAP") -> Covered | I17: 2 | J17: =IF(E17=0,"No item mapped",IF(F17=E17,"All items scored",F17&" of "&E17&" items scored")) -> 0 of 4 items scored
A18: 2.3.1 | B18: 2.3 High Availability & Resilience | C18: Review multi-Availability Zone architecture and fault-tolerance mechanisms. | D18: HA & Resilience | E18: =COUNTIF('HA & Resilience'!$F$5:$F$300,$A18) -> 6 | F18: =COUNTIFS('HA & Resilience'!$F$5:$F$300,$A18,'HA & Resilience'!$G$5:$G$300,">0") -> 0 | G18: =IFERROR(AVERAGEIFS('HA & Resilience'!$G$5:$G$300,'HA & Resilience'!$F$5:$F$300,$A18),"") | H18: =IF(E18>0,"Covered","GAP") -> Covered | I18: 3 | J18: =IF(E18=0,"No item mapped",IF(F18=E18,"All items scored",F18&" of "&E18&" items scored")) -> 0 of 6 items scored
A19: 2.3.2 | B19: 2.3 High Availability & Resilience | C19: Assess Availability Zone, network virtual appliance and Gateway Load Balancer target failure scenarios. | D19: HA & Resilience | E19: =COUNTIF('HA & Resilience'!$F$5:$F$300,$A19) -> 8 | F19: =COUNTIFS('HA & Resilience'!$F$5:$F$300,$A19,'HA & Resilience'!$G$5:$G$300,">0") -> 0 | G19: =IFERROR(AVERAGEIFS('HA & Resilience'!$G$5:$G$300,'HA & Resilience'!$F$5:$F$300,$A19),"") | H19: =IF(E19>0,"Covered","GAP") -> Covered | I19: 3 | J19: =IF(E19=0,"No item mapped",IF(F19=E19,"All items scored",F19&" of "&E19&" items scored")) -> 0 of 8 items scored
A20: 2.3.3 | B20: 2.3 High Availability & Resilience | C20: Review route convergence, recovery behavior and stateful session impact. | D20: HA & Resilience | E20: =COUNTIF('HA & Resilience'!$F$5:$F$300,$A20) -> 5 | F20: =COUNTIFS('HA & Resilience'!$F$5:$F$300,$A20,'HA & Resilience'!$G$5:$G$300,">0") -> 0 | G20: =IFERROR(AVERAGEIFS('HA & Resilience'!$G$5:$G$300,'HA & Resilience'!$F$5:$F$300,$A20),"") | H20: =IF(E20>0,"Covered","GAP") -> Covered | I20: 3 | J20: =IF(E20=0,"No item mapped",IF(F20=E20,"All items scored",F20&" of "&E20&" items scored")) -> 0 of 5 items scored
A21: 2.3.4 | B21: 2.3 High Availability & Resilience | C21: Identify asymmetric-routing risks. | D21: HA & Resilience | E21: =COUNTIF('HA & Resilience'!$F$5:$F$300,$A21) -> 4 | F21: =COUNTIFS('HA & Resilience'!$F$5:$F$300,$A21,'HA & Resilience'!$G$5:$G$300,">0") -> 0 | G21: =IFERROR(AVERAGEIFS('HA & Resilience'!$G$5:$G$300,'HA & Resilience'!$F$5:$F$300,$A21),"") | H21: =IF(E21>0,"Covered","GAP") -> Covered | I21: 3 | J21: =IF(E21=0,"No item mapped",IF(F21=E21,"All items scored",F21&" of "&E21&" items scored")) -> 0 of 4 items scored
A22: 2.3.5 | B22: 2.3 High Availability & Resilience | C22: Define practical failover scenarios and expected results for UAT. | D22: HA & Resilience | E22: =COUNTIF('HA & Resilience'!$F$5:$F$300,$A22) -> 6 | F22: =COUNTIFS('HA & Resilience'!$F$5:$F$300,$A22,'HA & Resilience'!$G$5:$G$300,">0") -> 0 | G22: =IFERROR(AVERAGEIFS('HA & Resilience'!$G$5:$G$300,'HA & Resilience'!$F$5:$F$300,$A22),"") | H22: =IF(E22>0,"Covered","GAP") -> Covered | I22: 3 | J22: =IF(E22=0,"No item mapped",IF(F22=E22,"All items scored",F22&" of "&E22&" items scored")) -> 0 of 6 items scored
A23: 2.4.1 | B23: 2.4 Third-Party Integration | C23: Review integration with network virtual appliances and firewalls. | D23: Third-Party Integration | E23: =COUNTIF('Third-Party Integration'!$F$5:$F$300,$A23) -> 8 | F23: =COUNTIFS('Third-Party Integration'!$F$5:$F$300,$A23,'Third-Party Integration'!$G$5:$G$300,">0") -> 0 | G23: =IFERROR(AVERAGEIFS('Third-Party Integration'!$G$5:$G$300,'Third-Party Integration'!$F$5:$F$300,$A23),"") | H23: =IF(E23>0,"Covered","GAP") -> Covered | I23: 4 | J23: =IF(E23=0,"No item mapped",IF(F23=E23,"All items scored",F23&" of "&E23&" items scored")) -> 0 of 8 items scored
A24: 2.4.2 | B24: 2.4 Third-Party Integration | C24: Review integration with IPS/IDS and WAF solutions. | D24: Third-Party Integration | E24: =COUNTIF('Third-Party Integration'!$F$5:$F$300,$A24) -> 6 | F24: =COUNTIFS('Third-Party Integration'!$F$5:$F$300,$A24,'Third-Party Integration'!$G$5:$G$300,">0") -> 0 | G24: =IFERROR(AVERAGEIFS('Third-Party Integration'!$G$5:$G$300,'Third-Party Integration'!$F$5:$F$300,$A24),"") | H24: =IF(E24>0,"Covered","GAP") -> Covered | I24: 4 | J24: =IF(E24=0,"No item mapped",IF(F24=E24,"All items scored",F24&" of "&E24&" items scored")) -> 0 of 6 items scored
A25: 2.4.3 | B25: 2.4 Third-Party Integration | C25: Review integration with proxy and security inspection services. | D25: Third-Party Integration | E25: =COUNTIF('Third-Party Integration'!$F$5:$F$300,$A25) -> 5 | F25: =COUNTIFS('Third-Party Integration'!$F$5:$F$300,$A25,'Third-Party Integration'!$G$5:$G$300,">0") -> 0 | G25: =IFERROR(AVERAGEIFS('Third-Party Integration'!$G$5:$G$300,'Third-Party Integration'!$F$5:$F$300,$A25),"") | H25: =IF(E25>0,"Covered","GAP") -> Covered | I25: 4 | J25: =IF(E25=0,"No item mapped",IF(F25=E25,"All items scored",F25&" of "&E25&" items scored")) -> 0 of 5 items scored
A26: 2.4.4 | B26: 2.4 Third-Party Integration | C26: GENEVE compatibility, health checks, routing, return paths and inspection-chain dependencies. | D26: Third-Party Integration | E26: =COUNTIF('Third-Party Integration'!$F$5:$F$300,$A26) -> 10 | F26: =COUNTIFS('Third-Party Integration'!$F$5:$F$300,$A26,'Third-Party Integration'!$G$5:$G$300,">0") -> 0 | G26: =IFERROR(AVERAGEIFS('Third-Party Integration'!$G$5:$G$300,'Third-Party Integration'!$F$5:$F$300,$A26),"") | H26: =IF(E26>0,"Covered","GAP") -> Covered | I26: 4 | J26: =IF(E26=0,"No item mapped",IF(F26=E26,"All items scored",F26&" of "&E26&" items scored")) -> 0 of 10 items scored
A27: 2.5.1 | B27: 2.5 Migration & Cutover Readiness | C27: Review the migration strategy and traffic switchover sequence. | D27: Migration & Cutover | E27: =COUNTIF('Migration & Cutover'!$F$5:$F$300,$A27) -> 8 | F27: =COUNTIFS('Migration & Cutover'!$F$5:$F$300,$A27,'Migration & Cutover'!$G$5:$G$300,">0") -> 0 | G27: =IFERROR(AVERAGEIFS('Migration & Cutover'!$G$5:$G$300,'Migration & Cutover'!$F$5:$F$300,$A27),"") | H27: =IF(E27>0,"Covered","GAP") -> Covered | I27: 5 | J27: =IF(E27=0,"No item mapped",IF(F27=E27,"All items scored",F27&" of "&E27&" items scored")) -> 0 of 8 items scored
A28: 2.5.2 | B28: 2.5 Migration & Cutover Readiness | C28: Review rollback procedures, triggers and service-restoration criteria. | D28: Migration & Cutover | E28: =COUNTIF('Migration & Cutover'!$F$5:$F$300,$A28) -> 5 | F28: =COUNTIFS('Migration & Cutover'!$F$5:$F$300,$A28,'Migration & Cutover'!$G$5:$G$300,">0") -> 0 | G28: =IFERROR(AVERAGEIFS('Migration & Cutover'!$G$5:$G$300,'Migration & Cutover'!$F$5:$F$300,$A28),"") | H28: =IF(E28>0,"Covered","GAP") -> Covered | I28: 5 | J28: =IF(E28=0,"No item mapped",IF(F28=E28,"All items scored",F28&" of "&E28&" items scored")) -> 0 of 5 items scored
A29: 2.5.3 | B29: 2.5 Migration & Cutover Readiness | C29: Identify cutover dependencies and potential traffic black-hole windows. | D29: Migration & Cutover | E29: =COUNTIF('Migration & Cutover'!$F$5:$F$300,$A29) -> 6 | F29: =COUNTIFS('Migration & Cutover'!$F$5:$F$300,$A29,'Migration & Cutover'!$G$5:$G$300,">0") -> 0 | G29: =IFERROR(AVERAGEIFS('Migration & Cutover'!$G$5:$G$300,'Migration & Cutover'!$F$5:$F$300,$A29),"") | H29: =IF(E29>0,"Covered","GAP") -> Covered | I29: 5 | J29: =IF(E29=0,"No item mapped",IF(F29=E29,"All items scored",F29&" of "&E29&" items scored")) -> 0 of 6 items scored
A30: 2.5.4 | B30: 2.5 Migration & Cutover Readiness | C30: Define go/no-go criteria. | D30: Migration & Cutover | E30: =COUNTIF('Migration & Cutover'!$F$5:$F$300,$A30) -> 4 | F30: =COUNTIFS('Migration & Cutover'!$F$5:$F$300,$A30,'Migration & Cutover'!$G$5:$G$300,">0") -> 0 | G30: =IFERROR(AVERAGEIFS('Migration & Cutover'!$G$5:$G$300,'Migration & Cutover'!$F$5:$F$300,$A30),"") | H30: =IF(E30>0,"Covered","GAP") -> Covered | I30: 5 | J30: =IF(E30=0,"No item mapped",IF(F30=E30,"All items scored",F30&" of "&E30&" items scored")) -> 0 of 4 items scored
A31: 2.5.5 | B31: 2.5 Migration & Cutover Readiness | C31: Provide production-readiness recommendation with risks and prerequisites. | D31: Migration & Cutover | E31: =COUNTIF('Migration & Cutover'!$F$5:$F$300,$A31) -> 4 | F31: =COUNTIFS('Migration & Cutover'!$F$5:$F$300,$A31,'Migration & Cutover'!$G$5:$G$300,">0") -> 0 | G31: =IFERROR(AVERAGEIFS('Migration & Cutover'!$G$5:$G$300,'Migration & Cutover'!$F$5:$F$300,$A31),"") | H31: =IF(E31>0,"Covered","GAP") -> Covered | I31: 5 | J31: =IF(E31=0,"No item mapped",IF(F31=E31,"All items scored",F31&" of "&E31&" items scored")) -> 0 of 4 items scored
A32: 3 | B32: 3. Key Deliverables | C32: Seven deliverables with minimum content (see Deliverables Tracker). | D32: Deliverables Tracker | H32: n/a | I32: 1-7 | J32: =COUNTIF('Deliverables Tracker'!$I$5:$I$11,"Accepted")&" of 7 deliverables accepted" -> 0 of 7 deliverables accepted
A33: 4 | B33: 4. Partner Responsibilities | C33: Consultants assigned; evidence-backed findings; FAB comments resolved; final artefacts submitted. | D33: Deliverables Tracker | H33: n/a | I33: 1-7 | J33: See Partner Responsibilities checklist
C35: Scope clauses with no mapped item (GAP): | E35: =COUNTIF($H$5:$H$31,"GAP") -> 0

Sheet Architecture Review
A1: ARCHITECTURE REVIEW
A2: SOW 2.1 | Requirements Alignment | VPC/CIDR/Subnet/AZ | Transit Gateway & Routing | DNS | IGW & NAT | ALB/NLB/GWLB | Terraform/CloudFormation
A4: ID | B4: Category | C4: Assessment Item | D4: Description / Expected State | E4: Evidence / Validation Method | F4: SOW Ref | G4: Score (1-5) | H4: RAG Status | I4: Findings | J4: Recommendations | K4: Owner | L4: Target Date
A5: Requirements Alignment (SOW 2.1.1)
A6: ARC-001 | B6: Requirements Alignment | C6: Requirements Baseline | D6: FAB security, availability and operational requirements for internet breakout are documented and every design decision is traceable to a requirement. | E6: FAB requirements register, HLD/LLD, design decision log, traceability matrix | F6: 2.1.1 | H6: =IF(G6="","",IF(G6<=RED_MAX,"RED",IF(G6<=AMBER_MAX,"AMBER","GREEN"))) | I6: [Enter findings] | J6: [Enter recommendations] | K6: [Assign] | L6: [Date]
A7: ARC-002 | B7: Requirements Alignment | C7: Security Standards Alignment | D7: Design meets FAB security standards: segmentation, centralised egress control, traffic inspection, logging, and encryption in transit. | E7: FAB security standards, control compliance matrix, design review workshop | F7: 2.1.1 | H7: =IF(G7="","",IF(G7<=RED_MAX,"RED",IF(G7<=AMBER_MAX,"AMBER","GREEN"))) | I7: [Enter findings] | J7: [Enter recommendations] | K7: [Assign] | L7: [Date]
A8: ARC-003 | B8: Requirements Alignment | C8: Availability & Recovery Targets | D8: Availability, RTO and RPO targets for internet connectivity are defined and the design demonstrably meets them. | E8: SLA/SLO documents, availability calculation, RTO/RPO sign-off | F8: 2.1.1 | H8: =IF(G8="","",IF(G8<=RED_MAX,"RED",IF(G8<=AMBER_MAX,"AMBER","GREEN"))) | I8: [Enter findings] | J8: [Enter recommendations] | K8: [Assign] | L8: [Date]
A9: ARC-004 | B9: Requirements Alignment | C9: Operational Requirements Alignment | D9: Operating model (monitoring, patching, change, on-call, runbooks) is defined and resourced for all breakout components. | E9: Operations handbook, RACI, runbook inventory, on-call rota | F9: 2.1.1 | H9: =IF(G9="","",IF(G9<=RED_MAX,"RED",IF(G9<=AMBER_MAX,"AMBER","GREEN"))) | I9: [Enter findings] | J9: [Enter recommendations] | K9: [Assign] | L9: [Date]
A10: ARC-005 | B10: Requirements Alignment | C10: Design Documentation Quality | D10: HLD, LLD, network diagrams, IP plan and data-flow diagrams are complete, current, version-controlled and formally approved. | E10: Architecture repository, approval records, diagram vs deployed-state comparison | F10: 2.1.1 | H10: =IF(G10="","",IF(G10<=RED_MAX,"RED",IF(G10<=AMBER_MAX,"AMBER","GREEN"))) | I10: [Enter findings] | J10: [Enter recommendations] | K10: [Assign] | L10: [Date]
A11: ARC-006 | B11: Requirements Alignment | C11: Landing Zone & Reference Architecture Fit | D11: Network, inspection and egress components sit in dedicated network/shared-services accounts, aligned to AWS Landing Zone and Security Reference Architecture patterns. | E11: AWS Organizations structure, account inventory, SRA gap comparison | F11: 2.1.1 | H11: =IF(G11="","",IF(G11<=RED_MAX,"RED",IF(G11<=AMBER_MAX,"AMBER","GREEN"))) | I11: [Enter findings] | J11: [Enter recommendations] | K11: [Assign] | L11: [Date]
A12: VPC, CIDR, Subnet & AZ Design (SOW 2.1.2)
A13: ARC-007 | B13: VPC, CIDR, Subnet & AZ Design | C13: VPC Topology & Roles | D13: VPC roles (ingress, egress, inspection, spoke, shared services) are clearly defined and the hub-and-spoke topology matches the approved design. | E13: VPC inventory across accounts/regions, topology diagram, tagging review | F13: 2.1.2 | H13: =IF(G13="","",IF(G13<=RED_MAX,"RED",IF(G13<=AMBER_MAX,"AMBER","GREEN"))) | I13: [Enter findings] | J13: [Enter recommendations] | K13: [Assign] | L13: [Date]
A14: ARC-008 | B14: VPC, CIDR, Subnet & AZ Design | C14: CIDR Planning & Non-Overlap | D14: VPC CIDRs are non-overlapping with on-premises and other VPCs, managed via IPAM, and have documented growth headroom. | E14: IPAM export, CIDR allocation register, overlap analysis script | F14: 2.1.2 | H14: =IF(G14="","",IF(G14<=RED_MAX,"RED",IF(G14<=AMBER_MAX,"AMBER","GREEN"))) | I14: [Enter findings] | J14: [Enter recommendations] | K14: [Assign] | L14: [Date]
A15: ARC-009 | B15: VPC, CIDR, Subnet & AZ Design | C15: Subnet Design & Sizing | D15: Subnets are tiered and separated (TGW attachment, GWLB endpoint, NAT/public, appliance, workload) with adequate sizing and dedicated small subnets for TGW attachments. | E15: Subnet inventory, route table association review, IP utilisation report | F15: 2.1.2 | H15: =IF(G15="","",IF(G15<=RED_MAX,"RED",IF(G15<=AMBER_MAX,"AMBER","GREEN"))) | I15: [Enter findings] | J15: [Enter recommendations] | K15: [Assign] | L15: [Date]
A16: ARC-010 | B16: VPC, CIDR, Subnet & AZ Design | C16: Availability Zone Placement & AZ-ID Consistency | D16: Components are placed in the required number of AZs and consistent AZ IDs (not just AZ names) are used across accounts so resources are truly co-located or separated as designed. | E16: AZ name-to-ID mapping per account, subnet/AZ inventory | F16: 2.1.2 | H16: =IF(G16="","",IF(G16<=RED_MAX,"RED",IF(G16<=AMBER_MAX,"AMBER","GREEN"))) | I16: [Enter findings] | J16: [Enter recommendations] | K16: [Assign] | L16: [Date]
A17: ARC-011 | B17: VPC, CIDR, Subnet & AZ Design | C17: NACL & Security Group Baseline | D17: NACLs and security groups on inspection, egress and endpoint subnets allow only required flows and cannot be used to bypass design intent. | E17: NACL/SG export, Reachability Analyzer, rule review | F17: 2.1.2 | H17: =IF(G17="","",IF(G17<=RED_MAX,"RED",IF(G17<=AMBER_MAX,"AMBER","GREEN"))) | I17: [Enter findings] | J17: [Enter recommendations] | K17: [Assign] | L17: [Date]
A18: ARC-012 | B18: VPC, CIDR, Subnet & AZ Design | C18: VPC Flow Logs & Network Visibility | D18: VPC Flow Logs are enabled for all VPCs/ENIs in the breakout path, centralised, retained per policy, and usable for path validation. | E18: Flow Log configuration export, log destination and retention settings | F18: 2.1.2 | H18: =IF(G18="","",IF(G18<=RED_MAX,"RED",IF(G18<=AMBER_MAX,"AMBER","GREEN"))) | I18: [Enter findings] | J18: [Enter recommendations] | K18: [Assign] | L18: [Date]
A19: Transit Gateway & Routing Controls (SOW 2.1.3)
A20: ARC-013 | B20: Transit Gateway & Routing Controls | C20: Transit Gateway Design | D20: TGW topology (single/multi-region, peering, RAM sharing), attachment types and ownership are documented and match the approved design. | E20: TGW configuration export, RAM shares, attachment inventory | F20: 2.1.3 | H20: =IF(G20="","",IF(G20<=RED_MAX,"RED",IF(G20<=AMBER_MAX,"AMBER","GREEN"))) | I20: [Enter findings] | J20: [Enter recommendations] | K20: [Assign] | L20: [Date]
A21: ARC-014 | B21: Transit Gateway & Routing Controls | C21: TGW Route Table Segmentation | D21: Separate TGW route tables exist for spoke, inspection, egress and on-premises domains with the intended associations. | E21: TGW route table and association export, segmentation matrix | F21: 2.1.3 | H21: =IF(G21="","",IF(G21<=RED_MAX,"RED",IF(G21<=AMBER_MAX,"AMBER","GREEN"))) | I21: [Enter findings] | J21: [Enter recommendations] | K21: [Assign] | L21: [Date]
A22: ARC-015 | B22: Transit Gateway & Routing Controls | C22: Route Propagation & Static Routes | D22: Propagation is limited to intended attachments, static routes steer the default route to inspection, and there is no unintended route leakage between domains. | E22: TGW route tables (propagated vs static), route leak analysis | F22: 2.1.3 | H22: =IF(G22="","",IF(G22<=RED_MAX,"RED",IF(G22<=AMBER_MAX,"AMBER","GREEN"))) | I22: [Enter findings] | J22: [Enter recommendations] | K22: [Assign] | L22: [Date]
A23: ARC-016 | B23: Transit Gateway & Routing Controls | C23: Default Route Control | D23: Default routes (0.0.0.0/0) exist only where explicitly required and no path to the internet bypasses inspection. | E23: VPC and TGW route table review, Reachability Analyzer tests | F23: 2.1.3 | H23: =IF(G23="","",IF(G23<=RED_MAX,"RED",IF(G23<=AMBER_MAX,"AMBER","GREEN"))) | I23: [Enter findings] | J23: [Enter recommendations] | K23: [Assign] | L23: [Date]
A24: ARC-017 | B24: Transit Gateway & Routing Controls | C24: VPC Route Table Design | D24: Route tables per subnet tier are correct (workload to TGW/GWLBe, firewall to NAT, NAT to IGW); no overlapping or unintended specific routes; blackhole routes are deliberate. | E24: Route table export per subnet tier, route table vs design comparison | F24: 2.1.3 | H24: =IF(G24="","",IF(G24<=RED_MAX,"RED",IF(G24<=AMBER_MAX,"AMBER","GREEN"))) | I24: [Enter findings] | J24: [Enter recommendations] | K24: [Assign] | L24: [Date]
A25: ARC-018 | B25: Transit Gateway & Routing Controls | C25: Appliance Mode Configuration | D25: Appliance mode is enabled on the inspection VPC TGW attachment so forward and return flows use the same AZ appliance. | E25: TGW attachment attributes, flow symmetry test | F25: 2.1.3 | H25: =IF(G25="","",IF(G25<=RED_MAX,"RED",IF(G25<=AMBER_MAX,"AMBER","GREEN"))) | I25: [Enter findings] | J25: [Enter recommendations] | K25: [Assign] | L25: [Date]
A26: ARC-019 | B26: Transit Gateway & Routing Controls | C26: Routing Change Guardrails | D26: IAM/SCP and Config controls prevent unauthorised route table, TGW or IGW changes; changes require approval and are audited. | E26: SCPs, IAM policies, AWS Config rules, CloudTrail sample | F26: 2.1.3 | H26: =IF(G26="","",IF(G26<=RED_MAX,"RED",IF(G26<=AMBER_MAX,"AMBER","GREEN"))) | I26: [Enter findings] | J26: [Enter recommendations] | K26: [Assign] | L26: [Date]
A27: ARC-020 | B27: Transit Gateway & Routing Controls | C27: TGW Quotas & Scalability | D27: Attachments, routes, bandwidth per attachment and flow limits are within quotas with documented headroom for growth. | E27: Service Quotas report, attachment/route counts, growth forecast | F27: 2.1.3 | H27: =IF(G27="","",IF(G27<=RED_MAX,"RED",IF(G27<=AMBER_MAX,"AMBER","GREEN"))) | I27: [Enter findings] | J27: [Enter recommendations] | K27: [Assign] | L27: [Date]
A28: ARC-021 | B28: Transit Gateway & Routing Controls | C28: Hybrid Routing (Direct Connect / VPN) | D28: On-premises connectivity via DX/VPN with TGW/DXGW is redundant; BGP advertisements are summarised and no unintended default route is leaked either way. | E28: BGP session and advertised/received prefix lists, DX/VPN topology | F28: 2.1.3 | H28: =IF(G28="","",IF(G28<=RED_MAX,"RED",IF(G28<=AMBER_MAX,"AMBER","GREEN"))) | I28: [Enter findings] | J28: [Enter recommendations] | K28: [Assign] | L28: [Date]
A29: DNS Architecture & Name Resolution (SOW 2.1.4)
A30: ARC-022 | B30: DNS Architecture & Name Resolution | C30: Route 53 Resolver Architecture | D30: Route 53 Resolver inbound/outbound endpoints and forwarding rules exist with ENIs in at least two AZs and adequate capacity. | E30: Resolver endpoint and rule configuration, ENI/AZ placement | F30: 2.1.4 | H30: =IF(G30="","",IF(G30<=RED_MAX,"RED",IF(G30<=AMBER_MAX,"AMBER","GREEN"))) | I30: [Enter findings] | J30: [Enter recommendations] | K30: [Assign] | L30: [Date]
A31: ARC-023 | B31: DNS Architecture & Name Resolution | C31: Private Hosted Zones & Split-Horizon | D31: Private hosted zones are associated with the correct VPCs (including cross-account) and split-horizon DNS is consistent between internal and external views. | E31: Hosted zone inventory, VPC associations, resolution tests | F31: 2.1.4 | H31: =IF(G31="","",IF(G31<=RED_MAX,"RED",IF(G31<=AMBER_MAX,"AMBER","GREEN"))) | I31: [Enter findings] | J31: [Enter recommendations] | K31: [Assign] | L31: [Date]
A32: ARC-024 | B32: DNS Architecture & Name Resolution | C32: Hybrid DNS Resolution | D32: On-premises to AWS name resolution works both ways with conditional forwarders, no forwarding loops, and resolver rules shared via RAM where needed. | E32: On-premises DNS forwarder config, resolver rule associations, dig/nslookup tests | F32: 2.1.4 | H32: =IF(G32="","",IF(G32<=RED_MAX,"RED",IF(G32<=AMBER_MAX,"AMBER","GREEN"))) | I32: [Enter findings] | J32: [Enter recommendations] | K32: [Assign] | L32: [Date]
A33: ARC-025 | B33: DNS Architecture & Name Resolution | C33: DNS Traffic Path & Egress Control | D33: DNS query paths are documented; direct outbound UDP/TCP 53 to the internet is blocked except approved resolvers; DNS Firewall or equivalent is used. | E33: Firewall rules for port 53, DNS Firewall rule groups, query logs | F33: 2.1.4 | H33: =IF(G33="","",IF(G33<=RED_MAX,"RED",IF(G33<=AMBER_MAX,"AMBER","GREEN"))) | I33: [Enter findings] | J33: [Enter recommendations] | K33: [Assign] | L33: [Date]
A34: ARC-026 | B34: DNS Architecture & Name Resolution | C34: DNS Resilience & Query Capacity | D34: DNS resolution has no single point of failure, per-ENI resolver query limits are not approached, and failure of a resolver endpoint does not impact resolution. | E34: Resolver query logs/metrics, endpoint failure test | F34: 2.1.4 | H34: =IF(G34="","",IF(G34<=RED_MAX,"RED",IF(G34<=AMBER_MAX,"AMBER","GREEN"))) | I34: [Enter findings] | J34: [Enter recommendations] | K34: [Assign] | L34: [Date]
A35: Internet Gateway & NAT Gateway Design (SOW 2.1.5)
A36: ARC-027 | B36: Internet Gateway & NAT Gateway Design | C36: Internet Gateway Placement | D36: IGWs are attached only to designated ingress/egress VPCs; no unintended IGW or public subnet exists in spoke VPCs. | E36: IGW inventory across accounts, Config rule, route tables with IGW targets | F36: 2.1.5 | H36: =IF(G36="","",IF(G36<=RED_MAX,"RED",IF(G36<=AMBER_MAX,"AMBER","GREEN"))) | I36: [Enter findings] | J36: [Enter recommendations] | K36: [Assign] | L36: [Date]
A37: ARC-028 | B37: Internet Gateway & NAT Gateway Design | C37: NAT Gateway Deployment Model | D37: NAT Gateways are deployed per AZ with AZ-local routing; public/private NAT type is appropriate; EIPs are correctly associated. | E37: NAT Gateway inventory, route tables per AZ | F37: 2.1.5 | H37: =IF(G37="","",IF(G37<=RED_MAX,"RED",IF(G37<=AMBER_MAX,"AMBER","GREEN"))) | I37: [Enter findings] | J37: [Enter recommendations] | K37: [Assign] | L37: [Date]
A38: ARC-029 | B38: Internet Gateway & NAT Gateway Design | C38: NAT Capacity & Port Allocation | D38: NAT Gateway bandwidth and per-destination connection limits meet peak demand; ErrorPortAllocation and packet-drop metrics are monitored with alarms. | E38: CloudWatch NAT metrics, peak connection analysis, alarm configuration | F38: 2.1.5 | H38: =IF(G38="","",IF(G38<=RED_MAX,"RED",IF(G38<=AMBER_MAX,"AMBER","GREEN"))) | I38: [Enter findings] | J38: [Enter recommendations] | K38: [Assign] | L38: [Date]
A39: ARC-030 | B39: Internet Gateway & NAT Gateway Design | C39: Elastic IP Management & Allow-Listing | D39: Egress EIPs are static, documented and allow-listed with third parties; EIP changes follow a controlled process including DR. | E39: EIP inventory, third-party allow-list register | F39: 2.1.5 | H39: =IF(G39="","",IF(G39<=RED_MAX,"RED",IF(G39<=AMBER_MAX,"AMBER","GREEN"))) | I39: [Enter findings] | J39: [Enter recommendations] | K39: [Assign] | L39: [Date]
A40: ARC-031 | B40: Internet Gateway & NAT Gateway Design | C40: IPv6 & Egress-Only IGW | D40: IPv6 strategy is defined; egress-only IGW is used where applicable and IPv6 traffic is inspected equivalently to IPv4. | E40: IPv6 CIDR inventory, egress-only IGW config, inspection policy for IPv6 | F40: 2.1.5 | H40: =IF(G40="","",IF(G40<=RED_MAX,"RED",IF(G40<=AMBER_MAX,"AMBER","GREEN"))) | I40: [Enter findings] | J40: [Enter recommendations] | K40: [Assign] | L40: [Date]
A41: ARC-032 | B41: Internet Gateway & NAT Gateway Design | C41: Public IP Exposure Controls | D41: No unintended public IPs/EIPs are assigned to workload resources; SCP/Config guardrails prevent them. | E41: Public IP inventory, Config conformance, SCPs | F41: 2.1.5 | H41: =IF(G41="","",IF(G41<=RED_MAX,"RED",IF(G41<=AMBER_MAX,"AMBER","GREEN"))) | I41: [Enter findings] | J41: [Enter recommendations] | K41: [Assign] | L41: [Date]
...

Sheet Traffic Flow Validation
A1: TRAFFIC FLOW VALIDATION
A2: SOW 2.2 | Inbound / Outbound / East-West | L3-L7 Paths | Routing Symmetry & Return Path | Service Insertion | Control Placement & Steering
A4: ID | B4: Category | C4: Assessment Item | D4: Description / Expected State | E4: Evidence / Validation Method | F4: SOW Ref | G4: Score (1-5) | H4: RAG Status | I4: Findings | J4: Recommendations | K4: Owner | L4: Target Date
A5: Inbound Flows (SOW 2.2.1)
A6: TRF-001 | B6: Inbound Flows | C6: Inbound Internet Path Documentation | D6: The inbound path (internet, edge services, load balancer, inspection, workload) is documented hop-by-hop and matches the deployed configuration. | E6: Flow diagrams, route tables, Reachability Analyzer, traceroute | F6: 2.2.1 | H6: =IF(G6="","",IF(G6<=RED_MAX,"RED",IF(G6<=AMBER_MAX,"AMBER","GREEN"))) | I6: [Enter findings] | J6: [Enter recommendations] | K6: [Assign] | L6: [Date]
A7: TRF-002 | B7: Inbound Flows | C7: Inbound Route Steering | D7: Ingress traffic is steered through inspection as designed (e.g., IGW edge route table to GWLB endpoints) with no bypass path to workloads. | E7: IGW edge association and route tables, test from external source | F7: 2.2.1 | H7: =IF(G7="","",IF(G7<=RED_MAX,"RED",IF(G7<=AMBER_MAX,"AMBER","GREEN"))) | I7: [Enter findings] | J7: [Enter recommendations] | K7: [Assign] | L7: [Date]
A8: TRF-003 | B8: Inbound Flows | C8: Public Exposure Inventory | D8: All internet-facing endpoints (EIPs, load balancer DNS names, API endpoints) are inventoried and each maps to an approved flow. | E8: Public IP/EIP/LB inventory, external attack-surface scan | F8: 2.2.1 | H8: =IF(G8="","",IF(G8<=RED_MAX,"RED",IF(G8<=AMBER_MAX,"AMBER","GREEN"))) | I8: [Enter findings] | J8: [Enter recommendations] | K8: [Assign] | L8: [Date]
A9: TRF-004 | B9: Inbound Flows | C9: Inbound Port & Rule Enforcement | D9: Only required ports/protocols are reachable from the internet; SG, NACL and firewall rules enforce this. | E9: Reachability Analyzer, authorised port scan, rule review | F9: 2.2.1 | H9: =IF(G9="","",IF(G9<=RED_MAX,"RED",IF(G9<=AMBER_MAX,"AMBER","GREEN"))) | I9: [Enter findings] | J9: [Enter recommendations] | K9: [Assign] | L9: [Date]
A10: TRF-005 | B10: Inbound Flows | C10: Client Source IP Preservation | D10: Client IP is preserved or recoverable (X-Forwarded-For, proxy protocol) through the load balancer and appliance chain for logging and ACLs. | E10: Sample packet/log analysis at each hop, LB attribute review | F10: 2.2.1 | H10: =IF(G10="","",IF(G10<=RED_MAX,"RED",IF(G10<=AMBER_MAX,"AMBER","GREEN"))) | I10: [Enter findings] | J10: [Enter recommendations] | K10: [Assign] | L10: [Date]
A11: Outbound Flows (SOW 2.2.1)
A12: TRF-006 | B12: Outbound Flows | C12: Outbound Internet Path Documentation | D12: The outbound path (workload, TGW, inspection, NAT, IGW) is documented and centralised vs distributed egress is consistent with the design. | E12: Flow diagrams, route tables, traceroute from workloads in each VPC | F12: 2.2.1 | H12: =IF(G12="","",IF(G12<=RED_MAX,"RED",IF(G12<=AMBER_MAX,"AMBER","GREEN"))) | I12: [Enter findings] | J12: [Enter recommendations] | K12: [Assign] | L12: [Date]
A13: TRF-007 | B13: Outbound Flows | C13: Egress Bypass Testing | D13: Tests confirm no workload VPC or subnet can reach the internet without inspection (direct IGW/NAT, other attachments, misconfigured routes). | E13: Egress test matrix from each spoke VPC/AZ, route analysis | F13: 2.2.1 | H13: =IF(G13="","",IF(G13<=RED_MAX,"RED",IF(G13<=AMBER_MAX,"AMBER","GREEN"))) | I13: [Enter findings] | J13: [Enter recommendations] | K13: [Assign] | L13: [Date]
A14: TRF-008 | B14: Outbound Flows | C14: Egress Filtering Effectiveness | D14: Egress policy is effective: approved destinations succeed and blocked categories/ports/domains fail as intended. | E14: Positive/negative egress tests, firewall logs | F14: 2.2.1 | H14: =IF(G14="","",IF(G14<=RED_MAX,"RED",IF(G14<=AMBER_MAX,"AMBER","GREEN"))) | I14: [Enter findings] | J14: [Enter recommendations] | K14: [Assign] | L14: [Date]
A15: TRF-009 | B15: Outbound Flows | C15: Outbound Protocol Coverage | D15: Non-HTTP(S) protocols (SSH, SMTP, NTP, DNS, ICMP, UDP) are handled by explicit policy with default deny. | E15: Protocol test matrix, firewall policy review | F15: 2.2.1 | H15: =IF(G15="","",IF(G15<=RED_MAX,"RED",IF(G15<=AMBER_MAX,"AMBER","GREEN"))) | I15: [Enter findings] | J15: [Enter recommendations] | K15: [Assign] | L15: [Date]
A16: TRF-010 | B16: Outbound Flows | C16: SNAT & Source Attribution | D16: External parties see the expected egress EIPs and internal source attribution remains available for logging after NAT. | E16: External echo test, NAT and flow log correlation | F16: 2.2.1 | H16: =IF(G16="","",IF(G16<=RED_MAX,"RED",IF(G16<=AMBER_MAX,"AMBER","GREEN"))) | I16: [Enter findings] | J16: [Enter recommendations] | K16: [Assign] | L16: [Date]
A17: East-West Flows (SOW 2.2.1)
A18: TRF-011 | B18: East-West Flows | C18: East-West Segmentation Policy | D18: Spoke-to-spoke traffic via TGW follows a documented segmentation matrix (production, non-production, shared services) and is enforced. | E18: Segmentation matrix, TGW route tables, connectivity tests | F18: 2.2.1 | H18: =IF(G18="","",IF(G18<=RED_MAX,"RED",IF(G18<=AMBER_MAX,"AMBER","GREEN"))) | I18: [Enter findings] | J18: [Enter recommendations] | K18: [Assign] | L18: [Date]
A19: TRF-012 | B19: East-West Flows | C19: Intra-VPC Cross-Subnet / Cross-AZ Flows | D19: East-west flows inside a VPC are controlled (SG/NACL or inspection insertion) as designed and cross-AZ paths are understood. | E19: SG/NACL review, flow logs, Reachability Analyzer | F19: 2.2.1 | H19: =IF(G19="","",IF(G19<=RED_MAX,"RED",IF(G19<=AMBER_MAX,"AMBER","GREEN"))) | I19: [Enter findings] | J19: [Enter recommendations] | K19: [Assign] | L19: [Date]
A20: TRF-013 | B20: East-West Flows | C20: East-West Inspection Coverage | D20: Which east-west flows are inspected vs bypass is documented; exceptions are risk-accepted. | E20: Inspection coverage matrix, exception register | F20: 2.2.1 | H20: =IF(G20="","",IF(G20<=RED_MAX,"RED",IF(G20<=AMBER_MAX,"AMBER","GREEN"))) | I20: [Enter findings] | J20: [Enter recommendations] | K20: [Assign] | L20: [Date]
A21: TRF-014 | B21: East-West Flows | C21: Shared Services Access Paths | D21: DNS, directory, patching, monitoring and management flows to shared services are validated and inspected as designed. | E21: Shared services flow list, connectivity tests | F21: 2.2.1 | H21: =IF(G21="","",IF(G21<=RED_MAX,"RED",IF(G21<=AMBER_MAX,"AMBER","GREEN"))) | I21: [Enter findings] | J21: [Enter recommendations] | K21: [Assign] | L21: [Date]
A22: Hybrid & AWS Service Flows (SOW 2.2.1)
A23: TRF-015 | B23: Hybrid & AWS Service Flows | C23: Hybrid Ingress / Egress Flows | D23: On-premises to AWS and AWS to on-premises flows traverse the expected inspection and routing path over DX/VPN. | E23: Path tests both directions, BGP/route review, firewall logs | F23: 2.2.1 | H23: =IF(G23="","",IF(G23<=RED_MAX,"RED",IF(G23<=AMBER_MAX,"AMBER","GREEN"))) | I23: [Enter findings] | J23: [Enter recommendations] | K23: [Assign] | L23: [Date]
A24: TRF-016 | B24: Hybrid & AWS Service Flows | C24: AWS Service Access Paths | D24: Access to S3, DynamoDB and other AWS services uses VPC endpoints or defined paths rather than unintended internet routes; endpoint policies are restrictive. | E24: Endpoint inventory, route review, endpoint policy review | F24: 2.2.1 | H24: =IF(G24="","",IF(G24<=RED_MAX,"RED",IF(G24<=AMBER_MAX,"AMBER","GREEN"))) | I24: [Enter findings] | J24: [Enter recommendations] | K24: [Assign] | L24: [Date]
A25: Layer 3 / Layer 7 Path Validation (SOW 2.2.2)
A26: TRF-017 | B26: Layer 3 / Layer 7 Path Validation | C26: L3/L4 Path Validation | D26: Reachability Analyzer and traceroute results for each defined flow match the expected hop sequence. | E26: Reachability Analyzer reports, traceroute/mtr captures | F26: 2.2.2 | H26: =IF(G26="","",IF(G26<=RED_MAX,"RED",IF(G26<=AMBER_MAX,"AMBER","GREEN"))) | I26: [Enter findings] | J26: [Enter recommendations] | K26: [Assign] | L26: [Date]
A27: TRF-018 | B27: Layer 3 / Layer 7 Path Validation | C27: L7 Path & Proxy Validation | D27: Explicit or transparent proxy handling of HTTP/S is validated including proxy chaining, PAC/WPAD distribution and authentication. | E27: Proxy configuration, client proxy settings, test requests | F27: 2.2.2 | H27: =IF(G27="","",IF(G27<=RED_MAX,"RED",IF(G27<=AMBER_MAX,"AMBER","GREEN"))) | I27: [Enter findings] | J27: [Enter recommendations] | K27: [Assign] | L27: [Date]
A28: TRF-019 | B28: Layer 3 / Layer 7 Path Validation | C28: TLS Inspection Path | D28: It is documented where TLS is terminated or decrypted, trust certificates are deployed, exclusions (pinned apps) are recorded and performance is acceptable. | E28: TLS inspection policy, CA distribution evidence, exclusion list | F28: 2.2.2 | H28: =IF(G28="","",IF(G28<=RED_MAX,"RED",IF(G28<=AMBER_MAX,"AMBER","GREEN"))) | I28: [Enter findings] | J28: [Enter recommendations] | K28: [Assign] | L28: [Date]
A29: TRF-020 | B29: Layer 3 / Layer 7 Path Validation | C29: Firewall Rule Path Dependencies | D29: Firewall policies match the intended flows; rule ordering is correct with no shadowed or any-any rules that undermine controls. | E29: Firewall rule base export, shadow/overly-permissive rule analysis | F29: 2.2.2 | H29: =IF(G29="","",IF(G29<=RED_MAX,"RED",IF(G29<=AMBER_MAX,"AMBER","GREEN"))) | I29: [Enter findings] | J29: [Enter recommendations] | K29: [Assign] | L29: [Date]
A30: TRF-021 | B30: Layer 3 / Layer 7 Path Validation | C30: Load Balancing Dependencies in Path | D30: For every flow, ALB/NLB/GWLB dependencies (health checks, targets, listener rules) are documented, with the failure impact of each. | E30: Dependency map, load balancer configuration, failure impact analysis | F30: 2.2.2 | H30: =IF(G30="","",IF(G30<=RED_MAX,"RED",IF(G30<=AMBER_MAX,"AMBER","GREEN"))) | I30: [Enter findings] | J30: [Enter recommendations] | K30: [Assign] | L30: [Date]
A31: Routing Symmetry & Return Paths (SOW 2.2.3)
A32: TRF-022 | B32: Routing Symmetry & Return Paths | C32: Return Path Design | D32: The return path for every flow is identified and passes through the same inspection appliance/AZ as the forward path. | E32: Return path diagrams, route tables for return direction | F32: 2.2.3 | H32: =IF(G32="","",IF(G32<=RED_MAX,"RED",IF(G32<=AMBER_MAX,"AMBER","GREEN"))) | I32: [Enter findings] | J32: [Enter recommendations] | K32: [Assign] | L32: [Date]
A33: TRF-023 | B33: Routing Symmetry & Return Paths | C33: Routing Symmetry Verification | D33: Packet captures or flow logs prove both directions traverse the same appliance; appliance mode is validated. | E33: Packet capture at appliance, VPC Flow Logs, appliance session logs | F33: 2.2.3 | H33: =IF(G33="","",IF(G33<=RED_MAX,"RED",IF(G33<=AMBER_MAX,"AMBER","GREEN"))) | I33: [Enter findings] | J33: [Enter recommendations] | K33: [Assign] | L33: [Date]
A34: TRF-024 | B34: Routing Symmetry & Return Paths | C34: Cross-AZ Symmetry Under Load Balancer Settings | D34: With AZ-local routing and cross-zone load balancing settings, flows remain symmetric across AZs including under failover. | E34: Cross-zone settings, multi-AZ flow tests, failover symmetry test | F34: 2.2.3 | H34: =IF(G34="","",IF(G34<=RED_MAX,"RED",IF(G34<=AMBER_MAX,"AMBER","GREEN"))) | I34: [Enter findings] | J34: [Enter recommendations] | K34: [Assign] | L34: [Date]
A35: Service Insertion & Inspection Flows (SOW 2.2.4)
A36: TRF-025 | B36: Service Insertion & Inspection Flows | C36: Service Insertion Architecture | D36: Inspection insertion points (ingress, egress, east-west) use GWLB endpoints per AZ and route tables reference them as designed. | E36: GWLBe inventory, route tables pointing to GWLBe | F36: 2.2.4 | H36: =IF(G36="","",IF(G36<=RED_MAX,"RED",IF(G36<=AMBER_MAX,"AMBER","GREEN"))) | I36: [Enter findings] | J36: [Enter recommendations] | K36: [Assign] | L36: [Date]
A37: TRF-026 | B37: Service Insertion & Inspection Flows | C37: Inspection Chain Ordering | D37: The order of chained services (e.g., firewall, IPS, proxy, WAF) and each hop's failure behaviour is documented and tested. | E37: Service chain diagram, per-hop failure behaviour tests | F37: 2.2.4 | H37: =IF(G37="","",IF(G37<=RED_MAX,"RED",IF(G37<=AMBER_MAX,"AMBER","GREEN"))) | I37: [Enter findings] | J37: [Enter recommendations] | K37: [Assign] | L37: [Date]
A38: TRF-027 | B38: Service Insertion & Inspection Flows | C38: Inspection Flow Visibility | D38: Appliance logs and flow logs prove each in-scope flow is inspected; no uninspected path exists. | E38: Appliance logs, flow logs, inspection coverage test | F38: 2.2.4 | H38: =IF(G38="","",IF(G38<=RED_MAX,"RED",IF(G38<=AMBER_MAX,"AMBER","GREEN"))) | I38: [Enter findings] | J38: [Enter recommendations] | K38: [Assign] | L38: [Date]
A39: Security Control Placement & Traffic Steering (SOW 2.2.5)
A40: TRF-028 | B40: Security Control Placement & Traffic Steering | C40: Security Control Placement | D40: Controls are placed at edge, inspection and workload layers per defence-in-depth with no reliance on a single layer. | E40: Control placement matrix, architecture review | F40: 2.2.5 | H40: =IF(G40="","",IF(G40<=RED_MAX,"RED",IF(G40<=AMBER_MAX,"AMBER","GREEN"))) | I40: [Enter findings] | J40: [Enter recommendations] | K40: [Assign] | L40: [Date]
A41: TRF-029 | B41: Security Control Placement & Traffic Steering | C41: Traffic Steering Mechanisms | D41: Route tables, TGW routes, GWLB endpoints and DNS steering are documented, deterministic and tested. | E41: Steering design, route configuration, path tests | F41: 2.2.5 | H41: =IF(G41="","",IF(G41<=RED_MAX,"RED",IF(G41<=AMBER_MAX,"AMBER","GREEN"))) | I41: [Enter findings] | J41: [Enter recommendations] | K41: [Assign] | L41: [Date]
...

Sheet Traffic Flow Matrix
A1: TRAFFIC FLOW VALIDATION MATRIX
A2: SOW 2.2 | Every flow validated for path, inspection point and return-path symmetry | Test each flow from every AZ and record evidence
A4: Flow ID | B4: Flow Type | C4: Flow Description | D4: Reference Pattern (AWS best practice - confirm vs FAB design) | E4: Actual Path per FAB Design | F4: Inspection Point(s) | G4: Protocols / Ports | H4: Return Path Symmetric? | I4: Validation Method | J4: Result | K4: Gap Identified / Finding Ref | L4: Linked Items | M4: Evidence Ref
A5: FLW-001 | B5: Inbound | C5: Internet client to public web application (ALB/NLB) | D5: Internet > IGW > [ingress inspection via GWLB endpoint] > ALB/NLB > target | E5: [Enter] | F5: [Enter] | G5: [Enter] | H5: Not Tested | I5: Reachability Analyzer from IGW; external test from each AZ endpoint; capture at appliance | J5: Not Tested | L5: TRF-001, TRF-002
A6: FLW-002 | B6: Inbound | C6: Internet client to application behind third-party WAF / IPS | D6: Internet > edge/WAF > inspection > load balancer > target | E6: [Enter] | F6: [Enter] | G6: [Enter] | H6: Not Tested | I6: External request tests; WAF and appliance log correlation; source-IP check | J6: Not Tested | L6: TRF-005, TPI-011
A7: FLW-003 | B7: Outbound | C7: Workload to internet via centralised egress | D7: Workload > TGW > inspection VPC (GWLB/appliance) > NAT Gateway > IGW > Internet | E7: [Enter] | F7: [Enter] | G7: [Enter] | H7: Not Tested | I7: Egress tests from each spoke VPC and AZ; traceroute; firewall and flow logs | J7: Not Tested | L7: TRF-006, TRF-007
A8: FLW-004 | B8: Outbound | C8: Workload HTTP/S via explicit or transparent proxy | D8: Workload > proxy (NLB/GWLB) > firewall > NAT > IGW | E8: [Enter] | F8: [Enter] | G8: [Enter] | H8: Not Tested | I8: Proxy configuration test; bypass attempt; proxy logs | J8: Not Tested | L8: TRF-018, TPI-015
A9: FLW-005 | B9: Outbound | C9: Workload to blocked destination (negative test) | D9: Workload > inspection > DROP | E9: [Enter] | F9: [Enter] | G9: [Enter] | H9: Not Tested | I9: Negative egress test; confirm block logged and no NAT session created | J9: Not Tested | L9: TRF-008
A10: FLW-006 | B10: DNS | C10: Workload DNS query resolution (internal and external) | D10: Workload > VPC resolver / Route 53 Resolver > forwarders/on-premises or public | E10: [Enter] | F10: [Enter] | G10: [Enter] | H10: Not Tested | I10: dig/nslookup from each VPC; resolver query logs; port 53 egress block test | J10: Not Tested | L10: ARC-022, TRF-009
A11: FLW-007 | B11: East-West | C11: Spoke VPC to spoke VPC via TGW | D11: Spoke A > TGW > [inspection VPC] > TGW > Spoke B | E11: [Enter] | F11: [Enter] | G11: [Enter] | H11: Not Tested | I11: Reachability Analyzer; flow logs both directions; segmentation matrix test | J11: Not Tested | L11: TRF-011, TRF-013
A12: FLW-008 | B12: East-West | C12: Cross-AZ flow within a VPC | D12: Subnet AZ-a > SG/NACL (or GWLBe) > Subnet AZ-b | E12: [Enter] | F12: [Enter] | G12: [Enter] | H12: Not Tested | I12: Flow logs; SG/NACL review; test with inspection endpoint if used | J12: Not Tested | L12: TRF-012
A13: FLW-009 | B13: East-West | C13: Workload to shared services (AD, patching, monitoring) | D13: Workload > TGW > shared services VPC | E13: [Enter] | F13: [Enter] | G13: [Enter] | H13: Not Tested | I13: Connectivity and port tests; inspection coverage check | J13: Not Tested | L13: TRF-014
A14: FLW-010 | B14: Hybrid | C14: AWS workload to on-premises | D14: Workload > TGW > DX/VPN attachment > on-premises firewall | E14: [Enter] | F14: [Enter] | G14: [Enter] | H14: Not Tested | I14: Path test both directions; BGP route check; firewall logs | J14: Not Tested | L14: TRF-015, ARC-021
A15: FLW-011 | B15: Hybrid | C15: On-premises to AWS workload | D15: On-premises > DX/VPN > TGW > [inspection] > Workload | E15: [Enter] | F15: [Enter] | G15: [Enter] | H15: Not Tested | I15: Path test; return-path symmetry check; segmentation validation | J15: Not Tested | L15: TRF-015
A16: FLW-012 | B16: AWS Service | C16: Workload to S3/DynamoDB via VPC endpoint | D16: Workload > gateway/interface endpoint > AWS service | E16: [Enter] | F16: [Enter] | G16: [Enter] | H16: Not Tested | I16: Route table check; endpoint policy test; confirm traffic not using NAT | J16: Not Tested | L16: TRF-016
... A20: FLW-016 | B20: Failover | C20: Flow behaviour after appliance/AZ failover | D20: Flow re-established via surviving AZ appliance without asymmetry | E20: [Enter] | F20: [Enter] | G20: [Enter] | H20: Not Tested | I20: Execute UAT-001/UAT-002; observe session and path | J20: Not Tested | L20: HAR-008, HAR-017
A21: FLW-017
A22: FLW-018
A23: FLW-019
A24: FLW-020
A25: FLW-021
A26: FLW-022
A27: FLW-023
A28: FLW-024

Sheet HA & Resilience
A1: HIGH AVAILABILITY & RESILIENCE REVIEW
A2: SOW 2.3 | Multi-AZ | AZ / NVA / GWLB Target Failure | Route Convergence & Stateful Sessions | Asymmetric Routing | UAT Failover Scenarios
A4: ID | B4: Category | C4: Assessment Item | D4: Description / Expected State | E4: Evidence / Validation Method | F4: SOW Ref | G4: Score (1-5) | H4: RAG Status | I4: Findings | J4: Recommendations | K4: Owner | L4: Target Date
A5: Multi-AZ Architecture & Fault Tolerance (SOW 2.3.1)
A6: HAR-001 | B6: Multi-AZ Architecture & Fault Tolerance | C6: Multi-AZ Deployment | D6: All breakout components (NAT, GWLB endpoints, appliances, TGW attachment subnets, resolver endpoints) span the number of AZs required by FAB. | E6: Component-to-AZ placement matrix, subnet/ENI inventory | F6: 2.3.1 | H6: =IF(G6="","",IF(G6<=RED_MAX,"RED",IF(G6<=AMBER_MAX,"AMBER","GREEN"))) | I6: [Enter findings] | J6: [Enter recommendations] | K6: [Assign] | L6: [Date]
A7: HAR-002 | B7: Multi-AZ Architecture & Fault Tolerance | C7: AZ-Independent Routing | D7: AZ-local (zonal) routing avoids cross-AZ dependency so an AZ failure does not impair other AZs. | E7: Route tables per AZ, cross-AZ path analysis | F7: 2.3.1 | H7: =IF(G7="","",IF(G7<=RED_MAX,"RED",IF(G7<=AMBER_MAX,"AMBER","GREEN"))) | I7: [Enter findings] | J7: [Enter recommendations] | K7: [Assign] | L7: [Date]
A8: HAR-003 | B8: Multi-AZ Architecture & Fault Tolerance | C8: Capacity for N-1 AZ | D8: Surviving AZs can carry full peak load (throughput, connections, licences) after loss of one AZ. | E8: Capacity model, load test results, licence limits | F8: 2.3.1 | H8: =IF(G8="","",IF(G8<=RED_MAX,"RED",IF(G8<=AMBER_MAX,"AMBER","GREEN"))) | I8: [Enter findings] | J8: [Enter recommendations] | K8: [Assign] | L8: [Date]
A9: HAR-004 | B9: Multi-AZ Architecture & Fault Tolerance | C9: Single Points of Failure Analysis | D9: A documented SPOF analysis covers all components and dependencies (EIPs, DNS, config sync, management plane, identity) with mitigations. | E9: SPOF analysis document, dependency map | F9: 2.3.1 | H9: =IF(G9="","",IF(G9<=RED_MAX,"RED",IF(G9<=AMBER_MAX,"AMBER","GREEN"))) | I9: [Enter findings] | J9: [Enter recommendations] | K9: [Assign] | L9: [Date]
